<?xml version="1.0"?>
<robot name="racecar" xmlns:xacro="http://www.ros.org/wiki/xacro">

  <!-- Include macros and materials -->
  <xacro:include filename="$(find f1tenth_description)/urdf/macros.xacro"/>
  <xacro:include filename="$(find f1tenth_description)/urdf/materials.xacro"/>

  <!-- Chassis -->
  <link name="chassis"/>
  <link name="base_link"/>
  <joint name="base_link_joint" type="fixed">
    <parent link="base_link"/>
    <child link="chassis"/>
    <origin xyz="0 0 0.05" rpy="0 0 0"/>
  </joint>

  <!-- Rear Wheels -->
  <link name="left_rear_wheel"/>
  <link name="right_rear_wheel"/>
  <joint name="left_rear_wheel_joint" type="continuous">
    <parent link="chassis"/>
    <child link="left_rear_wheel"/>
    <axis xyz="0 0 -1"/>
  </joint>
  <joint name="right_rear_wheel_joint" type="continuous">
    <parent link="chassis"/>
    <child link="right_rear_wheel"/>
    <axis xyz="0 0 -1"/>
  </joint>

  <!-- Steering Hinges -->
  <link name="left_steering_hinge"/>
  <link name="right_steering_hinge"/>
  <joint name="left_steering_hinge_joint" type="revolute">
    <parent link="chassis"/>
    <child link="left_steering_hinge"/>
    <axis xyz="-1 0 0"/>
    <limit lower="-1.0" upper="1.0"/>
  </joint>
  <joint name="right_steering_hinge_joint" type="revolute">
    <parent link="chassis"/>
    <child link="right_steering_hinge"/>
    <axis xyz="-1 0 0"/>
    <limit lower="-1.0" upper="1.0"/>
  </joint>

  <!-- Front Wheels -->
  <link name="left_front_wheel"/>
  <link name="right_front_wheel"/>
  <joint name="left_front_wheel_joint" type="continuous">
    <parent link="left_steering_hinge"/>
    <child link="left_front_wheel"/>
    <axis xyz="0 0 -1"/>
  </joint>
  <joint name="right_front_wheel_joint" type="continuous">
    <parent link="right_steering_hinge"/>
    <child link="right_front_wheel"/>
    <axis xyz="0 0 -1"/>
  </joint>

  <!-- ROS2 Control Section -->
  <ros2_control name="RaceCarHardware" type="system">
    <hardware>
      <plugin>gazebo_ros2_control/GazeboSystem</plugin>
    </hardware>

    <!-- Steering joints -->
    <joint name="left_steering_hinge_joint">
      <command_interface name="position"/>
      <state_interface name="position"/>
      <state_interface name="velocity"/>
    </joint>
    <joint name="right_steering_hinge_joint">
      <command_interface name="position"/>
      <state_interface name="position"/>
      <state_interface name="velocity"/>
    </joint>

    <!-- Rear wheels -->
    <joint name="left_rear_wheel_joint">
      <command_interface name="velocity"/>
      <state_interface name="position"/>
      <state_interface name="velocity"/>
    </joint>
    <joint name="right_rear_wheel_joint">
      <command_interface name="velocity"/>
      <state_interface name="position"/>
      <state_interface name="velocity"/>
    </joint>

    <!-- Front wheels (optional for Gazebo physics) -->
    <joint name="left_front_wheel_joint">
      <command_interface name="velocity"/>
      <state_interface name="position"/>
      <state_interface name="velocity"/>
    </joint>
    <joint name="right_front_wheel_joint">
      <command_interface name="velocity"/>
      <state_interface name="position"/>
      <state_interface name="velocity"/>
    </joint>
  </ros2_control>

</robot>
